Workbook
Name Business_Col: #REF!
Name DONE_DONE_DONE: _xlfn.VSTACK([1]Inhand_Dynamic!$BF$2:$BH$3,_xlfn.HSTACK(_xlfn.ANCHORARRAY([1]Inhand_Dynamic!$BF$4),_xlfn.ANCHORARRAY( [1]Inhand_Dynamic!$BG$4),_xlfn.ANCHORARRAY( [1]Inhand_Dynamic!$BH$4)))
Name Summmary_Col2: #REF!

Sheet FY_25-26
B1: Formula | S1: Formula | T1: Formula
A2: BUSINESS UNITS | B2: SR. NO. | C2: SUPPLIER | D2: BRAND | E2: BUYER NAME | F2: DEPARTMENT | G2: CATEGORY | H2: STYLE NO | I2: NEW/REBUY | J2: COLOR | K2: PO NO | L2: COUNTRY | M2: Supplier Ref. No. | N2: Product Description | O2: UK PO RECD DATE | P2: TOTAL ORDER QTY | Q2: USD PRICE PER PC | R2: GBP PRICE PER PC | S2: USD TOTAL PO VALUE | T2: GBP TOTAL PO VALUE | U2: CONFIRMED EX-FACTORY | V2: REVISED EX- FACTORY | W2: Delivery Date | X2: MODE | Y2: Port of loading | Z2: Sample approved status | AA2: Sustainable | AB2: Incoterms
A3: =IF('FY_25-26'!$D3="","",IF(OR('FY_25-26'!$D3="BOOHOO LADIES",'FY_25-26'!$D3="PLT",'FY_25-26'!$D3="KM"),"BUSINESS UNIT 1 - KIRAN","BUSINESS UNIT 2 - SHIFALI")) -> BUSINESS UNIT 2 - SHIFALI | B3: =IF('FY_25-26'!$C3<>"",ROW()-ROW($B$2),"") -> 1 | C3: BANSWARA | D3: BURTON | E3: ISABELLA CHAPMAN | F3: LADIES | G3: SOFT WOVEN | H3: BBB05806 | I3: REBUY | J3: BLACK | K3: 3380602 | L3: UK | M3: AA6661683F1 | N3: Black SkinnyFit TuxedoSuit Trouserblack | O3: 45902 | P3: 200 | Q3: 16.8 | R3: - | S3: =IF($Q3="","",IF($Q3="-","-",$P3*$Q3)) -> 3360 | T3: =IF($R3="","",IF($R3="-","-",$P3*$R3)) -> - | U3: 46090 | V3: - | X3: FOB SEA | Y3: INMUD | Z3: NO | AA3: NO Info | AB3: FOB
A4: =IF('FY_25-26'!$D4="","",IF(OR('FY_25-26'!$D4="BOOHOO LADIES",'FY_25-26'!$D4="PLT",'FY_25-26'!$D4="KM"),"BUSINESS UNIT 1 - KIRAN","BUSINESS UNIT 2 - SHIFALI")) -> BUSINESS UNIT 2 - SHIFALI | B4: =IF('FY_25-26'!$C4<>"",ROW()-ROW($B$2),"") -> 2 | C4: BANSWARA | D4: BURTON | E4: ISABELLA CHAPMAN | F4: LADIES | G4: SOFT WOVEN | H4: BBB05802 | I4: REBUY | J4: BLACK | K4: 3380603 | L4: UK | M4: AA66608F1B | N4: Black SlimFit TuxedoSuit Jacketblack | O4: 45902 | P4: 351 | Q4: 17 | R4: - | S4: =IF($Q4="","",IF($Q4="-","-",$P4*$Q4)) -> 5967 | T4: =IF($R4="","",IF($R4="-","-",$P4*$R4)) -> - | U4: 46090 | V4: - | X4: FOB SEA | Y4: INMUD | Z4: NO | AA4: NO Info | AB4: FOB
A5: =IF('FY_25-26'!$D5="","",IF(OR('FY_25-26'!$D5="BOOHOO LADIES",'FY_25-26'!$D5="PLT",'FY_25-26'!$D5="KM"),"BUSINESS UNIT 1 - KIRAN","BUSINESS UNIT 2 - SHIFALI")) -> BUSINESS UNIT 2 - SHIFALI | B5: =IF('FY_25-26'!$C5<>"",ROW()-ROW($B$2),"") -> 3 | C5: BANSWARA | D5: BURTON | E5: ISABELLA CHAPMAN | F5: LADIES | G5: SOFT WOVEN | H5: BBB05803 | I5: REBUY | J5: BLACK | K5: 3380601 | L5: UK | M5: AA6661683F | N5: Black SlimFit TuxedoSuit Trouserblack | O5: 45902 | P5: 453 | Q5: 8.25 | R5: - | S5: =IF($Q5="","",IF($Q5="-","-",$P5*$Q5)) -> 3737.25 | T5: =IF($R5="","",IF($R5="-","-",$P5*$R5)) -> - | U5: 46090 | V5: - | X5: FOB SEA | Y5: INMUD | Z5: NO | AA5: NO Info | AB5: FOB
A6: =IF('FY_25-26'!$D6="","",IF(OR('FY_25-26'!$D6="BOOHOO LADIES",'FY_25-26'!$D6="PLT",'FY_25-26'!$D6="KM"),"BUSINESS UNIT 1 - KIRAN","BUSINESS UNIT 2 - SHIFALI")) -> BUSINESS UNIT 2 - SHIFALI | B6: =IF('FY_25-26'!$C6<>"",ROW()-ROW($B$2),"") -> 4 | C6: BANSWARA | D6: BURTON | E6: ISABELLA CHAPMAN | F6: LADIES | G6: SOFT WOVEN | H6: BBB05804 | I6: REBUY | J6: BLACK | K6: 3380596 | L6: UK | M6: AA66616988 | N6: Black SlimFit TuxedoSuitWaistcoatblack | O6: 45902 | P6: 198 | Q6: 9.5 | R6: - | S6: =IF($Q6="","",IF($Q6="-","-",$P6*$Q6)) -> 1881 | T6: =IF($R6="","",IF($R6="-","-",$P6*$R6)) -> - | U6: 46153 | V6: - | X6: FOB SEA | Y6: INMUD | Z6: NO | AA6: NO Info | AB6: FOB
A7: =IF('FY_25-26'!$D7="","",IF(OR('FY_25-26'!$D7="BOOHOO LADIES",'FY_25-26'!$D7="PLT",'FY_25-26'!$D7="KM"),"BUSINESS UNIT 1 - KIRAN","BUSINESS UNIT 2 - SHIFALI")) -> BUSINESS UNIT 2 - SHIFALI | B7: =IF('FY_25-26'!$C7<>"",ROW()-ROW($B$2),"") -> 5 | C7: WINDESON TRADEMART | D7: NASTYGAL | E7: GEORGIA MAY BARTOSZ | F7: LADIES | G7: SOFT WOVEN | H7: BGG27898 | I7: NEW | J7: GREEN | K7: 3380680 | L7: UK | M7: GB68B69844 | N7: Check Asymmetric Cap Sleeve Top | O7: 45902 | P7: 100 | Q7: - | R7: 5.82 | S7: =IF($Q7="","",IF($Q7="-","-",$P7*$Q7)) -> - | T7: =IF($R7="","",IF($R7="-","-",$P7*$R7)) -> 582 | U7: 45978 | V7: 46003 | X7: FOB AIR | Y7: INDEL | Z7: NO | AA7: NO Info | AB7: FOB
A8: =IF('FY_25-26'!$D8="","",IF(OR('FY_25-26'!$D8="BOOHOO LADIES",'FY_25-26'!$D8="PLT",'FY_25-26'!$D8="KM"),"BUSINESS UNIT 1 - KIRAN","BUSINESS UNIT 2 - SHIFALI")) -> BUSINESS UNIT 2 - SHIFALI | B8: =IF('FY_25-26'!$C8<>"",ROW()-ROW($B$2),"") -> 6 | C8: WINDESON TRADEMART | D8: NASTYGAL | E8: GEORGIA MAY BARTOSZ | F8: LADIES | G8: SOFT WOVEN | H8: BGG27899 | I8: NEW | J8: GREEN | K8: 3380681 | L8: UK | M8: GB68B6F737 | N8: Check Wrap Maxi Skirt | O8: 45902 | P8: 100 | Q8: - | R8: 7.47 | S8: =IF($Q8="","",IF($Q8="-","-",$P8*$Q8)) -> - | T8: =IF($R8="","",IF($R8="-","-",$P8*$R8)) -> 747 | U8: 46006 | V8: 46001 | X8: FOB AIR | Y8: INDEL | Z8: NO | AA8: NO Info | AB8: FOB
A9: =IF('FY_25-26'!$D9="","",IF(OR('FY_25-26'!$D9="BOOHOO LADIES",'FY_25-26'!$D9="PLT",'FY_25-26'!$D9="KM"),"BUSINESS UNIT 1 - KIRAN","BUSINESS UNIT 2 - SHIFALI")) -> BUSINESS UNIT 2 - SHIFALI | B9: =IF('FY_25-26'!$C9<>"",ROW()-ROW($B$2),"") -> 7 | C9: BANSWARA | D9: BURTON | E9: OLIVIA KANE | F9: MEN | G9: SOFT WOVEN | H9: BBB06058 | I9: REBUY | J9: BLACK | K9: 3380999 | L9: UK | M9: AA66FC0105 | N9: BlackRegular FitSuitTrousersblack | O9: 45904 | P9: 100 | Q9: 9.15 | R9: - | S9: =IF($Q9="","",IF($Q9="-","-",$P9*$Q9)) -> 915 | T9: =IF($R9="","",IF($R9="-","-",$P9*$R9)) -> - | U9: 46153 | V9: - | X9: FOB SEA | Y9: INMUD | Z9: NO | AA9: NO Info | AB9: FOB
A10: =IF('FY_25-26'!$D10="","",IF(OR('FY_25-26'!$D10="BOOHOO LADIES",'FY_25-26'!$D10="PLT",'FY_25-26'!$D10="KM"),"BUSINESS UNIT 1 - KIRAN","BUSINESS UNIT 2 - SHIFALI")) -> BUSINESS UNIT 2 - SHIFALI | B10: =IF('FY_25-26'!$C10<>"",ROW()-ROW($B$2),"") -> 8 | C10: BANSWARA | D10: BURTON | E10: OLIVIA KANE | F10: MEN | G10: SOFT WOVEN | H10: BBB06056 | I10: REBUY | J10: NAVY | K10: 3380998 | L10: UK | M10: AA66FBFF87 | N10: NavyRegular FitSuitTrousersnavy | O10: 45904 | P10: 150 | Q10: 9.15 | R10: - | S10: =IF($Q10="","",IF($Q10="-","-",$P10*$Q10)) -> 1372.5 | T10: =IF($R10="","",IF($R10="-","-",$P10*$R10)) -> - | U10: 46118 | V10: - | X10: FOB SEA | Y10: INMUD | Z10: NO | AA10: NO Info | AB10: FOB
A11: =IF('FY_25-26'!$D11="","",IF(OR('FY_25-26'!$D11="BOOHOO LADIES",'FY_25-26'!$D11="PLT",'FY_25-26'!$D11="KM"),"BUSINESS UNIT 1 - KIRAN","BUSINESS UNIT 2 - SHIFALI")) -> BUSINESS UNIT 2 - SHIFALI | B11: =IF('FY_25-26'!$C11<>"",ROW()-ROW($B$2),"") -> 9 | C11: BANSWARA | D11: BURTON | E11: OLIVIA KANE | F11: MEN | G11: SOFT WOVEN | H11: BBB06056 | I11: REBUY | J11: NAVY | K11: 3381000 | L11: UK | M11: AA66FBFF87 | N11: NavyRegular FitSuitTrousersnavy | O11: 45904 | P11: 200 | Q11: 9.15 | R11: - | S11: =IF($Q11="","",IF($Q11="-","-",$P11*$Q11)) -> 1830 | T11: =IF($R11="","",IF($R11="-","-",$P11*$R11)) -> - | U11: 46062 | V11: - | X11: FOB SEA | Y11: INMUD | Z11: NO | AA11: NO Info | AB11: FOB
A12: =IF('FY_25-26'!$D12="","",IF(OR('FY_25-26'!$D12="BOOHOO LADIES",'FY_25-26'!$D12="PLT",'FY_25-26'!$D12="KM"),"BUSINESS UNIT 1 - KIRAN","BUSINESS UNIT 2 - SHIFALI")) -> BUSINESS UNIT 2 - SHIFALI | B12: =IF('FY_25-26'!$C12<>"",ROW()-ROW($B$2),"") -> 10 | C12: BANSWARA | D12: BURTON | E12: OLIVIA KANE | F12: MEN | G12: SOFT WOVEN | H12: BBB06055 | I12: REBUY | J12: NAVY | K12: 3381001 | L12: UK | M12: AA66FBFD51 | N12: NavyRegular FitSuit Jacketnavy | O12: 45904 | P12: 150 | Q12: 18.2 | R12: - | S12: =IF($Q12="","",IF($Q12="-","-",$P12*$Q12)) -> 2730 | T12: =IF($R12="","",IF($R12="-","-",$P12*$R12)) -> - | U12: 46118 | V12: - | X12: FOB SEA | Y12: INMUD | Z12: NO | AA12: NO Info | AB12: FOB
A13: =IF('FY_25-26'!$D13="","",IF(OR('FY_25-26'!$D13="BOOHOO LADIES",'FY_25-26'!$D13="PLT",'FY_25-26'!$D13="KM"),"BUSINESS UNIT 1 - KIRAN","BUSINESS UNIT 2 - SHIFALI")) -> BUSINESS UNIT 2 - SHIFALI | B13: =IF('FY_25-26'!$C13<>"",ROW()-ROW($B$2),"") -> 11 | C13: WINDESON TRADEMART | D13: NASTYGAL | E13: GEORGIA MAY BARTOSZ | F13: LADIES | G13: SOFT WOVEN | H13: BGG27906 | I13: NEW | J13: LEMON | K13: 3381208 | L13: UK | M13: GB68B84DF3 | N13: ChiffonPaintedFloral GodetCowl MaxiDresslemon | O13: 45904 | P13: 100 | Q13: - | R13: 9.9 | S13: =IF($Q13="","",IF($Q13="-","-",$P13*$Q13)) -> - | T13: =IF($R13="","",IF($R13="-","-",$P13*$R13)) -> 990 | U13: 46006 | V13: - | X13: FOB SEA | Y13: INMUD | Z13: NO | AA13: NO Info | AB13: FOB
A14: =IF('FY_25-26'!$D14="","",IF(OR('FY_25-26'!$D14="BOOHOO LADIES",'FY_25-26'!$D14="PLT",'FY_25-26'!$D14="KM"),"BUSINESS UNIT 1 - KIRAN","BUSINESS UNIT 2 - SHIFALI")) -> BUSINESS UNIT 2 - SHIFALI | B14: =IF('FY_25-26'!$C14<>"",ROW()-ROW($B$2),"") -> 12 | C14: N&A Design | D14: WALLIS | E14: FLORENCE DRIVER | F14: LADIES | G14: SOFT WOVEN | H14: BYY17071 | I14: NEW | J14: PINK | K14: 3381389 | L14: UK | M14: SS26-EH054 | N14: MeshPleatedTwist WaistMidi Dresspink | O14: 45904 | P14: 120 | Q14: - | R14: 14 | S14: =IF($Q14="","",IF($Q14="-","-",$P14*$Q14)) -> - | T14: =IF($R14="","",IF($R14="-","-",$P14*$R14)) -> 1680 | U14: 45993 | V14: 46014 | X14: FOB SEA | Y14: INMUD | Z14: NO | AA14: NO Info | AB14: FOB
A15: =IF('FY_25-26'!$D15="","",IF(OR('FY_25-26'!$D15="BOOHOO LADIES",'FY_25-26'!$D15="PLT",'FY_25-26'!$D15="KM"),"BUSINESS UNIT 1 - KIRAN","BUSINESS UNIT 2 - SHIFALI")) -> BUSINESS UNIT 2 - SHIFALI | B15: =IF('FY_25-26'!$C15<>"",ROW()-ROW($B$2),"") -> 13 | C15: N&A Design | D15: WALLIS | E15: FLORENCE DRIVER | F15: LADIES | G15: SOFT WOVEN | H15: BYY17072 | I15: NEW | J15: NAVY | K15: 3381390 | L15: UK | M15: BYY09831 | N15: Floral MeshSatin TieMidi Dressnavy | O15: 45904 | P15: 153 | Q15: - | R15: 12.5 | S15: =IF($Q15="","",IF($Q15="-","-",$P15*$Q15)) -> - | T15: =IF($R15="","",IF($R15="-","-",$P15*$R15)) -> 1912.5 | U15: 45993 | V15: - | X15: FOB SEA | Y15: INMUD | Z15: NO | AA15: NO Info | AB15: FOB
A16: =IF('FY_25-26'!$D16="","",IF(OR('FY_25-26'!$D16="BOOHOO LADIES",'FY_25-26'!$D16="PLT",'FY_25-26'!$D16="KM"),"BUSINESS UNIT 1 - KIRAN","BUSINESS UNIT 2 - SHIFALI")) -> BUSINESS UNIT 2 - SHIFALI | B16: =IF('FY_25-26'!$C16<>"",ROW()-ROW($B$2),"") -> 14 | C16: N&A Design | D16: WALLIS | E16: FLORENCE DRIVER | F16: LADIES | G16: SOFT WOVEN | H16: BYY17073 | I16: NEW | J16: NAVY | K16: 3381391 | L16: UK | M16: KHSS26-123 | N16: Mesh Lace TrimMaxi Dress Navy | O16: 45904 | P16: 153 | Q16: - | R16: 12 | S16: =IF($Q16="","",IF($Q16="-","-",$P16*$Q16)) -> - | T16: =IF($R16="","",IF($R16="-","-",$P16*$R16)) -> 1836 | U16: 45993 | V16: 46014 | X16: FOB SEA | Y16: INMUD | Z16: NO | AA16: NO Info | AB16: FOB
A17: =IF('FY_25-26'!$D17="","",IF(OR('FY_25-26'!$D17="BOOHOO LADIES",'FY_25-26'!$D17="PLT",'FY_25-26'!$D17="KM"),"BUSINESS UNIT 1 - KIRAN","BUSINESS UNIT 2 - SHIFALI")) -> BUSINESS UNIT 2 - SHIFALI | B17: =IF('FY_25-26'!$C17<>"",ROW()-ROW($B$2),"") -> 15 | C17: N&A Design | D17: WALLIS | E17: FLORENCE DRIVER | F17: LADIES | G17: SOFT WOVEN | H17: BYY17073 | I17: NEW | J17: BLUSH | K17: 3381391 | L17: UK | M17: KHSS26-123 | N17: Mesh Lace TrimMaxi Dress Navy | O17: 45904 | P17: 153 | Q17: - | R17: 12 | S17: =IF($Q17="","",IF($Q17="-","-",$P17*$Q17)) -> - | T17: =IF($R17="","",IF($R17="-","-",$P17*$R17)) -> 1836 | U17: 45993 | V17: 46007 | X17: FOB SEA | Y17: INMUD | Z17: NO | AA17: NO Info | AB17: FOB
A18: =IF('FY_25-26'!$D18="","",IF(OR('FY_25-26'!$D18="BOOHOO LADIES",'FY_25-26'!$D18="PLT",'FY_25-26'!$D18="KM"),"BUSINESS UNIT 1 - KIRAN","BUSINESS UNIT 2 - SHIFALI")) -> BUSINESS UNIT 2 - SHIFALI | B18: =IF('FY_25-26'!$C18<>"",ROW()-ROW($B$2),"") -> 16 | C18: N&A Design | D18: WALLIS | E18: FLORENCE DRIVER | F18: LADIES | G18: SOFT WOVEN | H18: BYY17070 | I18: NEW | J18: BLUE | K18: 3381388 | L18: UK | M18: SS26-EH054 | N18: Petite MeshPleatedTwist WaistMidi Dressblue | O18: 45904 | P18: 120 | Q18: - | R18: 14 | S18: =IF($Q18="","",IF($Q18="-","-",$P18*$Q18)) -> - | T18: =IF($R18="","",IF($R18="-","-",$P18*$R18)) -> 1680 | U18: 45993 | V18: 46014 | X18: FOB SEA | Y18: INMUD | Z18: NO | AA18: NO Info | AB18: FOB
A19: =IF('FY_25-26'!$D19="","",IF(OR('FY_25-26'!$D19="BOOHOO LADIES",'FY_25-26'!$D19="PLT",'FY_25-26'!$D19="KM"),"BUSINESS UNIT 1 - KIRAN","BUSINESS UNIT 2 - SHIFALI")) -> BUSINESS UNIT 2 - SHIFALI | B19: =IF('FY_25-26'!$C19<>"",ROW()-ROW($B$2),"") -> 17 | C19: MIR | D19: COAST | E19: EMMA HAMILTON | F19: LADIES | G19: SOFT WOVEN | H19: BCC10211 | I19: REBUY | J19: IVORY | K19: 3383261 | L19: UK | M19: OB1785 | N19: Beaded andEmbellishedCap SleeveFishtailWeddingDress ivory | O19: 45911 | P19: 151 | Q19: - | R19: 36.5 | S19: =IF($Q19="","",IF($Q19="-","-",$P19*$Q19)) -> - | T19: =IF($R19="","",IF($R19="-","-",$P19*$R19)) -> 5511.5 | U19: 46021 | V19: - | X19: FOB SEA | Y19: INMUD | Z19: NO | AA19: NO Info | AB19: FOB
A20: =IF('FY_25-26'!$D20="","",IF(OR('FY_25-26'!$D20="BOOHOO LADIES",'FY_25-26'!$D20="PLT",'FY_25-26'!$D20="KM"),"BUSINESS UNIT 1 - KIRAN","BUSINESS UNIT 2 - SHIFALI")) -> BUSINESS UNIT 2 - SHIFALI | B20: =IF('FY_25-26'!$C20<>"",ROW()-ROW($B$2),"") -> 18 | C20: MIR | D20: COAST | E20: EMMA HAMILTON | F20: LADIES | G20: SOFT WOVEN | H20: BCC06877 | I20: REBUY | J20: IVORY | K20: 3383262 | L20: UK | M20: bardotlong | N20: Bardot LongSleeveWrap SkirtMini Dressivory | O20: 45911 | P20: 200 | Q20: - | R20: 32.1 | S20: =IF($Q20="","",IF($Q20="-","-",$P20*$Q20)) -> - | T20: =IF($R20="","",IF($R20="-","-",$P20*$R20)) -> 6420 | U20: 46021 | V20: - | X20: FOB AIR | Y20: INDEL | Z20: NO | AA20: NO Info | AB20: FOB
A21: =IF('FY_25-26'!$D21="","",IF(OR('FY_25-26'!$D21="BOOHOO LADIES",'FY_25-26'!$D21="PLT",'FY_25-26'!$D21="KM"),"BUSINESS UNIT 1 - KIRAN","BUSINESS UNIT 2 - SHIFALI")) -> BUSINESS UNIT 2 - SHIFALI | B21: =IF('FY_25-26'!$C21<>"",ROW()-ROW($B$2),"") -> 19 | C21: WINDESON TRADEMART | D21: COAST | E21: EMMA HAMILTON | F21: LADIES | G21: SOFT WOVEN | H21: BCC06124 | I21: REBUY | J21: MALBEC | K21: 3383248 | L21: UK | M21: MegaRuffleGeorgette | N21: CoastHonouredRuffleGeorgetteMaxiBridesmaidDressmalbec | O21: 45911 | P21: 200 | Q21: - | R21: 11 | S21: =IF($Q21="","",IF($Q21="-","-",$P21*$Q21)) -> - | T21: =IF($R21="","",IF($R21="-","-",$P21*$R21)) -> 2200 | U21: 46019 | V21: - | X21: FOB AIR | Y21: INDEL | Z21: NO | AA21: NO Info | AB21: FOB
A22: =IF('FY_25-26'!$D22="","",IF(OR('FY_25-26'!$D22="BOOHOO LADIES",'FY_25-26'!$D22="PLT",'FY_25-26'!$D22="KM"),"BUSINESS UNIT 1 - KIRAN","BUSINESS UNIT 2 - SHIFALI")) -> BUSINESS UNIT 2 - SHIFALI | B22: =IF('FY_25-26'!$C22<>"",ROW()-ROW($B$2),"") -> 20 | C22: WINDESON TRADEMART | D22: COAST | E22: EMMA HAMILTON | F22: LADIES | G22: SOFT WOVEN | H22: BCC06124 | I22: REBUY | J22: NAVY | K22: 3383248 | L22: UK | M22: MegaRuffleGeorgette | N22: CoastHonouredRuffleGeorgetteMaxiBridesmaidDressmalbec | O22: 45911 | P22: 200 | Q22: - | R22: 11 | S22: =IF($Q22="","",IF($Q22="-","-",$P22*$Q22)) -> - | T22: =IF($R22="","",IF($R22="-","-",$P22*$R22)) -> 2200 | U22: 46019 | V22: - | X22: FOB AIR | Y22: INDEL | Z22: NO | AA22: NO Info | AB22: FOB
A23: =IF('FY_25-26'!$D23="","",IF(OR('FY_25-26'!$D23="BOOHOO LADIES",'FY_25-26'!$D23="PLT",'FY_25-26'!$D23="KM"),"BUSINESS UNIT 1 - KIRAN","BUSINESS UNIT 2 - SHIFALI")) -> BUSINESS UNIT 2 - SHIFALI | B23: =IF('FY_25-26'!$C23<>"",ROW()-ROW($B$2),"") -> 21 | C23: WINDESON TRADEMART | D23: NASTYGAL | E23: KIERAN DAVIES | F23: LADIES | G23: SOFT WOVEN | H23: BGG26907 | I23: REBUY | J23: BLACK | K23: 3383587 | L23: UK | M23: GB67ACC139 | N23: Floral LaceTrim CutOut MiniDress black | O23: 45911 | P23: 145 | Q23: - | R23: 6.85 | S23: =IF($Q23="","",IF($Q23="-","-",$P23*$Q23)) -> - | T23: =IF($R23="","",IF($R23="-","-",$P23*$R23)) -> 993.25 | U23: 45996 | V23: - | X23: FOB SEA | Y23: INMUD | Z23: NO | AA23: NO Info | AB23: FOB
A24: =IF('FY_25-26'!$D24="","",IF(OR('FY_25-26'!$D24="BOOHOO LADIES",'FY_25-26'!$D24="PLT",'FY_25-26'!$D24="KM"),"BUSINESS UNIT 1 - KIRAN","BUSINESS UNIT 2 - SHIFALI")) -> BUSINESS UNIT 2 - SHIFALI | B24: =IF('FY_25-26'!$C24<>"",ROW()-ROW($B$2),"") -> 22 | C24: STELLIFY | D24: NASTYGAL | E24: ANIA FAJGIER | F24: LADIES | G24: SOFT WOVEN | H24: BGG28163 | I24: NEW | J24: PURPLE | K24: 3390335 | L24: UK | M24: AF68D53B30 | N24: LobsterPrint SatinStripePajamaTrouser Setpurple | O24: 45932 | P24: 151 | Q24: - | R24: 7.75 | S24: =IF($Q24="","",IF($Q24="-","-",$P24*$Q24)) -> - | T24: =IF($R24="","",IF($R24="-","-",$P24*$R24)) -> 1170.25 | U24: 46020 | V24: - | X24: FOB AIR | Y24: INDEL | Z24: NO | AA24: NO Info | AB24: FOB
A25: =IF('FY_25-26'!$D25="","",IF(OR('FY_25-26'!$D25="BOOHOO LADIES",'FY_25-26'!$D25="PLT",'FY_25-26'!$D25="KM"),"BUSINESS UNIT 1 - KIRAN","BUSINESS UNIT 2 - SHIFALI")) -> BUSINESS UNIT 2 - SHIFALI | B25: =IF('FY_25-26'!$C25<>"",ROW()-ROW($B$2),"") -> 23 | C25: WINDESON TRADEMART | D25: NASTYGAL | E25: ABBIE HAWTHORN | F25: LADIES | G25: SOFT WOVEN | H25: BGG28159 | I25: NEW | J25: LEMON | K25: 3390286 | L25: UK | M25: GB68B84DF3 | N25: (AZ) ChiffonPaintedFloral GodetCowl MaxiDresslemon | O25: 45933 | P25: 100 | Q25: - | R25: 9.9 | S25: =IF($Q25="","",IF($Q25="-","-",$P25*$Q25)) -> - | T25: =IF($R25="","",IF($R25="-","-",$P25*$R25)) -> 990 | U25: 46006 | V25: 46034 | X25: FOB SEA | Y25: INMUD | Z25: NO | AA25: NO Info | AB25: FOB
A26: =IF('FY_25-26'!$D26="","",IF(OR('FY_25-26'!$D26="BOOHOO LADIES",'FY_25-26'!$D26="PLT",'FY_25-26'!$D26="KM"),"BUSINESS UNIT 1 - KIRAN","BUSINESS UNIT 2 - SHIFALI")) -> BUSINESS UNIT 2 - SHIFALI | B26: =IF('FY_25-26'!$C26<>"",ROW()-ROW($B$2),"") -> 24 | C26: WINDESON TRADEMART | D26: NASTYGAL | E26: ABBIE HAWTHORN | F26: LADIES | G26: SOFT WOVEN | H26: BGG28150 | I26: NEW | J26: GREEN | K26: 3390271 | L26: UK | M26: AW25WOV165EH | N26: (AZ) CheckLace TrimTie FrontMaxi Dressgreen | O26: 45933 | P26: 100 | Q26: - | R26: 11.55 | S26: =IF($Q26="","",IF($Q26="-","-",$P26*$Q26)) -> - | T26: =IF($R26="","",IF($R26="-","-",$P26*$R26)) -> 1155 | U26: 45999 | V26: 46011 | X26: FOB AIR | Y26: INDEL | Z26: NO | AA26: NO Info | AB26: FOB
A27: =IF('FY_25-26'!$D27="","",IF(OR('FY_25-26'!$D27="BOOHOO LADIES",'FY_25-26'!$D27="PLT",'FY_25-26'!$D27="KM"),"BUSINESS UNIT 1 - KIRAN","BUSINESS UNIT 2 - SHIFALI")) -> BUSINESS UNIT 2 - SHIFALI | B27: =IF('FY_25-26'!$C27<>"",ROW()-ROW($B$2),"") -> 25 | C27: AYAAN APPARELS | D27: NASTYGAL | E27: ABBIE HAWTHORN | F27: LADIES | G27: SOFT WOVEN | H27: BGG28147 | I27: NEW | J27: MONO | K27: 3390264 | L27: UK | M27: AW25WOV184EH | N27: (AZ) ChiffonPolka DotNeck TieElasticatedHem MiniDress mono | O27: 45933 | P27: 150 | Q27: - | R27: 6.25 | S27: =IF($Q27="","",IF($Q27="-","-",$P27*$Q27)) -> - | T27: =IF($R27="","",IF($R27="-","-",$P27*$R27)) -> 937.5 | U27: 45992 | V27: 46006 | X27: FOB AIR | Y27: INDEL | Z27: NO | AA27: NO Info | AB27: FOB
A28: =IF('FY_25-26'!$D28="","",IF(OR('FY_25-26'!$D28="BOOHOO LADIES",'FY_25-26'!$D28="PLT",'FY_25-26'!$D28="KM"),"BUSINESS UNIT 1 - KIRAN","BUSINESS UNIT 2 - SHIFALI")) -> BUSINESS UNIT 2 - SHIFALI | B28: =IF('FY_25-26'!$C28<>"",ROW()-ROW($B$2),"") -> 26 | C28: AYAAN APPARELS | D28: NASTYGAL | E28: ABBIE HAWTHORN | F28: LADIES | G28: SOFT WOVEN | H28: BGG28146 | I28: NEW | J28: BEIGE | K28: 3390260 | L28: UK | M28: AW25WOV188EH | N28: (AZ) ChiffonCheck RuffleBardot TieFront MiniDress beige | O28: 45933 | P28: 100 | Q28: - | R28: 6.75 | S28: =IF($Q28="","",IF($Q28="-","-",$P28*$Q28)) -> - | T28: =IF($R28="","",IF($R28="-","-",$P28*$R28)) -> 675 | U28: 45992 | V28: 46006 | X28: FOB AIR | Y28: INDEL | Z28: NO | AA28: NO Info | AB28: FOB
A29: =IF('FY_25-26'!$D29="","",IF(OR('FY_25-26'!$D29="BOOHOO LADIES",'FY_25-26'!$D29="PLT",'FY_25-26'!$D29="KM"),"BUSINESS UNIT 1 - KIRAN","BUSINESS UNIT 2 - SHIFALI")) -> BUSINESS UNIT 2 - SHIFALI | B29: =IF('FY_25-26'!$C29<>"",ROW()-ROW($B$2),"") -> 27 | C29: AYAAN APPARELS | D29: NASTYGAL | E29: ABBIE HAWTHORN | F29: LADIES | G29: SOFT WOVEN | H29: BGG28145 | I29: NEW | J29: BEIGE | K29: 3390259 | L29: UK | M29: AW25WOV190EH | N29: (AZ) ChiffonCheck CamiTop beige | O29: 45933 | P29: 100 | Q29: - | R29: 4.9 | S29: =IF($Q29="","",IF($Q29="-","-",$P29*$Q29)) -> - | T29: =IF($R29="","",IF($R29="-","-",$P29*$R29)) -> 490 | U29: 45992 | V29: 46006 | X29: FOB AIR | Y29: INDEL | Z29: NO | AA29: NO Info | AB29: FOB
A30: =IF('FY_25-26'!$D30="","",IF(OR('FY_25-26'!$D30="BOOHOO LADIES",'FY_25-26'!$D30="PLT",'FY_25-26'!$D30="KM"),"BUSINESS UNIT 1 - KIRAN","BUSINESS UNIT 2 - SHIFALI")) -> BUSINESS UNIT 2 - SHIFALI | B30: =IF('FY_25-26'!$C30<>"",ROW()-ROW($B$2),"") -> 28 | C30: AYAAN APPARELS | D30: NASTYGAL | E30: ABBIE HAWTHORN | F30: LADIES | G30: SOFT WOVEN | H30: BGG28144 | I30: NEW | J30: BEIGE | K30: 3390255 | L30: UK | M30: AW25WOV189EH | N30: (AZ) ChiffonCheck BiasMaxi Skirtbeige | O30: 45933 | P30: 100 | Q30: - | R30: 6.5 | S30: =IF($Q30="","",IF($Q30="-","-",$P30*$Q30)) -> - | T30: =IF($R30="","",IF($R30="-","-",$P30*$R30)) -> 650 | U30: 45992 | V30: 46006 | X30: FOB AIR | Y30: INDEL | Z30: NO | AA30: NO Info | AB30: FOB
A31: =IF('FY_25-26'!$D31="","",IF(OR('FY_25-26'!$D31="BOOHOO LADIES",'FY_25-26'!$D31="PLT",'FY_25-26'!$D31="KM"),"BUSINESS UNIT 1 - KIRAN","BUSINESS UNIT 2 - SHIFALI")) -> BUSINESS UNIT 2 - SHIFALI | B31: =IF('FY_25-26'!$C31<>"",ROW()-ROW($B$2),"") -> 29 | C31: U&I FASHION | D31: NASTYGAL | E31: GEORGIA MAY BARTOSZ | F31: LADIES | G31: SOFT WOVEN | H31: BGG28175 | I31: NEW | J31: CREAM | K31: 3391588 | L31: UK | M31: GB68DFD230 | N31: Lace Pearl Tassel Shirt | O31: 45938 | P31: 81 | Q31: 52.75 | R31: - | S31: =IF($Q31="","",IF($Q31="-","-",$P31*$Q31)) -> 4272.75 | T31: =IF($R31="","",IF($R31="-","-",$P31*$R31)) -> - | U31: 46041 | V31: - | X31: FOB AIR | Y31: INDEL | Z31: NO | AA31: NO Info | AB31: FOB
A32: =IF('FY_25-26'!$D32="","",IF(OR('FY_25-26'!$D32="BOOHOO LADIES",'FY_25-26'!$D32="PLT",'FY_25-26'!$D32="KM"),"BUSINESS UNIT 1 - KIRAN","BUSINESS UNIT 2 - SHIFALI")) -> BUSINESS UNIT 2 - SHIFALI | B32: =IF('FY_25-26'!$C32<>"",ROW()-ROW($B$2),"") -> 30 | C32: U&I FASHION | D32: NASTYGAL | E32: GEORGIA MAY BARTOSZ | F32: LADIES | G32: SOFT WOVEN | H32: BGG28174 | I32: NEW | J32: CREAM | K32: 3391589 | L32: UK | M32: GB68DFD083 | N32: Lace Pearl Tassel Trim Ruffle Open Back Mini Dress | O32: 45938 | P32: 81 | Q32: 48.75 | R32: - | S32: =IF($Q32="","",IF($Q32="-","-",$P32*$Q32)) -> 3948.75 | T32: =IF($R32="","",IF($R32="-","-",$P32*$R32)) -> - | U32: 46041 | V32: - | X32: FOB AIR | Y32: INDEL | Z32: NO | AA32: NO Info | AB32: FOB
A33: =IF('FY_25-26'!$D33="","",IF(OR('FY_25-26'!$D33="BOOHOO LADIES",'FY_25-26'!$D33="PLT",'FY_25-26'!$D33="KM"),"BUSINESS UNIT 1 - KIRAN","BUSINESS UNIT 2 - SHIFALI")) -> BUSINESS UNIT 2 - SHIFALI | B33: =IF('FY_25-26'!$C33<>"",ROW()-ROW($B$2),"") -> 31 | C33: U&I FASHION | D33: NASTYGAL | E33: GEORGIA MAY BARTOSZ | F33: LADIES | G33: SOFT WOVEN | H33: BGG28218 | I33: NEW | J33: BABY PINK | K33: 3397565 | L33: UK | M33: GB68A735ED | N33: Two Layer Disc Embellished Strappy Mini Dress | O33: 45933 | P33: 100 | Q33: 47 | R33: - | S33: =IF($Q33="","",IF($Q33="-","-",$P33*$Q33)) -> 4700 | T33: =IF($R33="","",IF($R33="-","-",$P33*$R33)) -> - | U33: 45992 | V33: 46006 | X33: FOB AIR | Y33: INDEL | Z33: NO | AA33: NO Info | AB33: FOB
A34: =IF('FY_25-26'!$D34="","",IF(OR('FY_25-26'!$D34="BOOHOO LADIES",'FY_25-26'!$D34="PLT",'FY_25-26'!$D34="KM"),"BUSINESS UNIT 1 - KIRAN","BUSINESS UNIT 2 - SHIFALI")) -> BUSINESS UNIT 2 - SHIFALI | B34: =IF('FY_25-26'!$C34<>"",ROW()-ROW($B$2),"") -> 32 | C34: CREST DESIGN | D34: DP | E34: SASKIA VERDERBER | F34: LADIES | G34: SOFT WOVEN | H34: BQQ23100 | I34: NEW | J34: PINK | K34: 3391190 | L34: UK | M34: SV68E3F2D1 | N34: (S) DitsyShirredBodice MidiDress pink | O34: 45937 | P34: 150 | Q34: - | R34: 7.95 | S34: =IF($Q34="","",IF($Q34="-","-",$P34*$Q34)) -> - | T34: =IF($R34="","",IF($R34="-","-",$P34*$R34)) -> 1192.5 | U34: 46000 | V34: - | X34: FOB SEA | Y34: INMUD | Z34: NO | AA34: NO Info | AB34: FOB
A35: =IF('FY_25-26'!$D35="","",IF(OR('FY_25-26'!$D35="BOOHOO LADIES",'FY_25-26'!$D35="PLT",'FY_25-26'!$D35="KM"),"BUSINESS UNIT 1 - KIRAN","BUSINESS UNIT 2 - SHIFALI")) -> BUSINESS UNIT 2 - SHIFALI | B35: =IF('FY_25-26'!$C35<>"",ROW()-ROW($B$2),"") -> 33 | C35: CREST DESIGN | D35: DP | E35: SASKIA VERDERBER | F35: LADIES | G35: SOFT WOVEN | H35: BQQ23099 | I35: NEW | J35: BLACK | K35: 3391189 | L35: UK | M35: SV68E3F24E | N35: (S) SpotButtonThroughFlutterSleeve MidiDress black | O35: 45937 | P35: 180 | Q35: - | R35: 7.55 | S35: =IF($Q35="","",IF($Q35="-","-",$P35*$Q35)) -> - | T35: =IF($R35="","",IF($R35="-","-",$P35*$R35)) -> 1359 | U35: 46000 | V35: - | X35: FOB SEA | Y35: INMUD | Z35: NO | AA35: NO Info | AB35: FOB
A36: =IF('FY_25-26'!$D36="","",IF(OR('FY_25-26'!$D36="BOOHOO LADIES",'FY_25-26'!$D36="PLT",'FY_25-26'!$D36="KM"),"BUSINESS UNIT 1 - KIRAN","BUSINESS UNIT 2 - SHIFALI")) -> BUSINESS UNIT 2 - SHIFALI | B36: =IF('FY_25-26'!$C36<>"",ROW()-ROW($B$2),"") -> 34 | C36: CREST DESIGN | D36: DP | E36: SASKIA VERDERBER | F36: LADIES | G36: SOFT WOVEN | H36: BQQ23098 | I36: NEW | J36: GREEN | K36: 3391188 | L36: UK | M36: SV68E3F15B | N36: (S) GreenAnimalFlutterSleeveShirredWaist MidiDress green | O36: 45937 | P36: 180 | Q36: - | R36: 6.45 | S36: =IF($Q36="","",IF($Q36="-","-",$P36*$Q36)) -> - | T36: =IF($R36="","",IF($R36="-","-",$P36*$R36)) -> 1161 | U36: 46000 | V36: - | X36: FOB SEA | Y36: INMUD | Z36: NO | AA36: NO Info | AB36: FOB
A37: =IF('FY_25-26'!$D37="","",IF(OR('FY_25-26'!$D37="BOOHOO LADIES",'FY_25-26'!$D37="PLT",'FY_25-26'!$D37="KM"),"BUSINESS UNIT 1 - KIRAN","BUSINESS UNIT 2 - SHIFALI")) -> BUSINESS UNIT 2 - SHIFALI | B37: =IF('FY_25-26'!$C37<>"",ROW()-ROW($B$2),"") -> 35 | C37: MIR | D37: COAST | E37: EMMA HAMILTION | F37: LADIES | G37: SOFT WOVEN | H37: BCC12753 | I37: NEW | J37: SAGE | K37: 3391142 | L37: UK | M37: BCC07492 | N37: Cap SleevePearlEmbellishedPencil Dresssage | O37: 45937 | P37: 151 | Q37: - | R37: 34 | S37: =IF($Q37="","",IF($Q37="-","-",$P37*$Q37)) -> - | T37: =IF($R37="","",IF($R37="-","-",$P37*$R37)) -> 5134 | U37: 46020 | V37: - | X37: FOB SEA | Y37: INMUD | Z37: NO | AA37: NO Info | AB37: FOB
A38: =IF('FY_25-26'!$D38="","",IF(OR('FY_25-26'!$D38="BOOHOO LADIES",'FY_25-26'!$D38="PLT",'FY_25-26'!$D38="KM"),"BUSINESS UNIT 1 - KIRAN","BUSINESS UNIT 2 - SHIFALI")) -> BUSINESS UNIT 2 - SHIFALI | B38: =IF('FY_25-26'!$C38<>"",ROW()-ROW($B$2),"") -> 36 | C38: MIR | D38: COAST | E38: EMMA HAMILTION | F38: LADIES | G38: SOFT WOVEN | H38: BCC12752 | I38: NEW | J38: LEMON | K38: 3391141 | L38: UK | M38: BCC07492 | N38: Cap SleevePearlEmbellishedPencil Dresslemon | O38: 45937 | P38: 151 | Q38: - | R38: 34 | S38: =IF($Q38="","",IF($Q38="-","-",$P38*$Q38)) -> - | T38: =IF($R38="","",IF($R38="-","-",$P38*$R38)) -> 5134 | U38: 45992 | V38: - | X38: FOB SEA | Y38: INMUD | Z38: NO | AA38: NO Info | AB38: FOB
A39: =IF('FY_25-26'!$D39="","",IF(OR('FY_25-26'!$D39="BOOHOO LADIES",'FY_25-26'!$D39="PLT",'FY_25-26'!$D39="KM"),"BUSINESS UNIT 1 - KIRAN","BUSINESS UNIT 2 - SHIFALI")) -> BUSINESS UNIT 2 - SHIFALI | B39: =IF('FY_25-26'!$C39<>"",ROW()-ROW($B$2),"") -> 37 | C39: AYAAN APPARELS | D39: NASTYGAL | E39: ABBIE HAWTHORN | F39: LADIES | G39: SOFT WOVEN | H39: BGG28171 | I39: NEW | J39: STEEL | K39: 3391084 | L39: UK | M39: AW25WOV063EH | N39: (Az) VelvetLace InsertButtonDetail CamiTop steel | O39: 45937 | P39: 252 | Q39: - | R39: 5.15 | S39: =IF($Q39="","",IF($Q39="-","-",$P39*$Q39)) -> - | T39: =IF($R39="","",IF($R39="-","-",$P39*$R39)) -> 1297.8 | U39: 45945 | V39: - | X39: FOB AIR | Y39: INDEL | Z39: NO | AA39: NO Info | AB39: FOB
A40: =IF('FY_25-26'!$D40="","",IF(OR('FY_25-26'!$D40="BOOHOO LADIES",'FY_25-26'!$D40="PLT",'FY_25-26'!$D40="KM"),"BUSINESS UNIT 1 - KIRAN","BUSINESS UNIT 2 - SHIFALI")) -> BUSINESS UNIT 2 - SHIFALI | B40: =IF('FY_25-26'!$C40<>"",ROW()-ROW($B$2),"") -> 38 | C40: AYAAN APPARELS | D40: NASTYGAL | E40: ABBIE HAWTHORN | F40: LADIES | G40: SOFT WOVEN | H40: BGG28170 | I40: NEW | J40: STEEL | K40: 3391077 | L40: UK | M40: AW25WOV052EH | N40: (AZ) VelvetLace TrimTie FrontMini Dresssteel | O40: 45937 | P40: 351 | Q40: - | R40: 6.9 | S40: =IF($Q40="","",IF($Q40="-","-",$P40*$Q40)) -> - | T40: =IF($R40="","",IF($R40="-","-",$P40*$R40)) -> 2421.9 | U40: 45945 | V40: - | X40: FOB AIR | Y40: INDEL | Z40: NO | AA40: NO Info | AB40: FOB
...
